Traceback (most recent call last):
  File "/pool/condor/dir_58256/run_analysis.py", line 81, in <module>
    myDF['Data'] = myDF['Path'].apply(adt.loadData)
  File "/afs/cern.ch/work/a/aradosla/private/miniforge3/lib/python3.10/site-packages/pandas/core/series.py", line 4771, in apply
    return SeriesApply(self, func, convert_dtype, args, kwargs).apply()
  File "/afs/cern.ch/work/a/aradosla/private/miniforge3/lib/python3.10/site-packages/pandas/core/apply.py", line 1123, in apply
    return self.apply_standard()
  File "/afs/cern.ch/work/a/aradosla/private/miniforge3/lib/python3.10/site-packages/pandas/core/apply.py", line 1174, in apply_standard
    mapped = lib.map_infer(
  File "pandas/_libs/lib.pyx", line 2924, in pandas._libs.lib.map_infer
  File "/pool/condor/dir_58256/run_analysis.py", line 40, in loadData
    fi = h5py.File(fileName, 'r')
  File "/afs/cern.ch/work/a/aradosla/private/miniforge3/lib/python3.10/site-packages/h5py/_hl/files.py", line 567, in __init__
    fid = make_fid(name, mode, userblock_size, fapl, fcpl, swmr=swmr)
  File "/afs/cern.ch/work/a/aradosla/private/miniforge3/lib/python3.10/site-packages/h5py/_hl/files.py", line 231, in make_fid
    fid = h5f.open(name, flags, fapl=fapl)
  File "h5py/_objects.pyx", line 54, in h5py._objects.with_phil.wrapper
  File "h5py/_objects.pyx", line 55, in h5py._objects.with_phil.wrapper
  File "h5py/h5f.pyx", line 106, in h5py.h5f.open
FileNotFoundError: [Errno 2] Unable to open file (unable to open file: name = 'ADTObsBox_data/B1H_Q7/31/5/B1H_Q7_20230331_05h45m51s638577us.h5', errno = 2, error message = 'No such file or directory', flags = 0, o_flags = 0)
